{"uuid": "b8088ff4-c0a5-4fcf-ae9d-b24fc1546d23", "children": ["59918434-7ad5-4420-a4d0-671fe3e1f656"], "befores": [{"name": "beforeClass", "status": "broken", "statusDetails": {"message": "selenium.common.exceptions.WebDriverException: Message: An unknown server-side error occurred while processing the command. Original error: Error executing adbExec. Original error: 'Command 'C:\\\\Users\\\\chandrakant\\\\AppData\\\\Local\\\\Android\\\\Sdk\\\\platform-tools\\\\adb.exe -P 5037 -s ef7239eb install -g C:\\\\Users\\\\chandrakant\\\\AppData\\\\Local\\\\Programs\\\\Appium\\\\resources\\\\app\\\\node_modules\\\\appium\\\\node_modules\\\\io.appium.settings\\\\apks\\\\settings_apk-debug.apk' exited with code 1'; Stderr: 'adb: failed to install C:\\Users\\chandrakant\\AppData\\Local\\Programs\\Appium\\resources\\app\\node_modules\\appium\\node_modules\\io.appium.settings\\apks\\settings_apk-debug.apk: \r\nException occurred while executing 'install':\r\njava.lang.SecurityException: You need the android.permission.INSTALL_GRANT_RUNTIME_PERMISSIONS permission to use the PackageManager.INSTALL_GRANT_RUNTIME_PERMISSIONS flag\r\n\tat com.android.server.pm.PackageInstallerService.createSessionInternal(PackageInstallerService.java:622)\r\n\tat com.android.server.pm.PackageInstallerService.createSession(PackageInstallerService.java:495)\r\n\tat com.android.server.pm.PackageManagerShellCommand.doCreateSession(PackageManagerShellC'; Code: '1'\nStacktrace:\nUnknownError: An unknown server-side error occurred while processing the command. Original error: Error executing adbExec. Original error: 'Command 'C:\\\\Users\\\\chandrakant\\\\AppData\\\\Local\\\\Android\\\\Sdk\\\\platform-tools\\\\adb.exe -P 5037 -s ef7239eb install -g C:\\\\Users\\\\chandrakant\\\\AppData\\\\Local\\\\Programs\\\\Appium\\\\resources\\\\app\\\\node_modules\\\\appium\\\\node_modules\\\\io.appium.settings\\\\apks\\\\settings_apk-debug.apk' exited with code 1'; Stderr: 'adb: failed to install C:\\Users\\chandrakant\\AppData\\Local\\Programs\\Appium\\resources\\app\\node_modules\\appium\\node_modules\\io.appium.settings\\apks\\settings_apk-debug.apk: \r\nException occurred while executing 'install':\r\njava.lang.SecurityException: You need the android.permission.INSTALL_GRANT_RUNTIME_PERMISSIONS permission to use the PackageManager.INSTALL_GRANT_RUNTIME_PERMISSIONS flag\r\n\tat com.android.server.pm.PackageInstallerService.createSessionInternal(PackageInstallerService.java:622)\r\n\tat com.android.server.pm.PackageInstallerService.createSession(PackageInstallerService.java:495)\r\n\tat com.android.server.pm.PackageManagerShellCommand.doCreateSession(PackageManagerShellC'; Code: '1'\n    at getResponseForW3CError (C:\\Users\\chandrakant\\AppData\\Local\\Programs\\Appium\\resources\\app\\node_modules\\appium\\node_modules\\appium-base-driver\\lib\\protocol\\errors.js:804:9)\n    at asyncHandler (C:\\Users\\chandrakant\\AppData\\Local\\Programs\\Appium\\resources\\app\\node_modules\\appium\\node_modules\\appium-base-driver\\lib\\protocol\\protocol.js:380:37)\n", "trace": "  File \"C:\\Users\\chandrakant\\AppData\\Local\\Programs\\Python\\Python39\\lib\\site-packages\\pluggy\\_callers.py\", line 39, in _multicall\n    res = hook_impl.function(*args)\n  File \"C:\\Users\\chandrakant\\AppData\\Local\\Programs\\Python\\Python39\\lib\\site-packages\\_pytest\\fixtures.py\", line 1126, in pytest_fixture_setup\n    result = call_fixture_func(fixturefunc, request, kwargs)\n  File \"C:\\Users\\chandrakant\\AppData\\Local\\Programs\\Python\\Python39\\lib\\site-packages\\_pytest\\fixtures.py\", line 925, in call_fixture_func\n    fixture_result = next(generator)\n  File \"C:\\Users\\chandrakant\\Documents\\GitHub\\CalculatorAppiumFramework\\calchan\\tests\\conftest.py\", line 10, in beforeClass\n    driver = driver1.getDriverMethod()\n  File \"C:\\Users\\chandrakant\\Documents\\GitHub\\CalculatorAppiumFramework\\calchan\\base\\DriverClass.py\", line 19, in getDriverMethod\n    driver = webdriver.Remote(\"http://127.0.0.1:4723/wd/hub\", desired_caps)\n  File \"C:\\Users\\chandrakant\\AppData\\Local\\Programs\\Python\\Python39\\lib\\site-packages\\appium\\webdriver\\webdriver.py\", line 267, in __init__\n    super().__init__(\n  File \"C:\\Users\\chandrakant\\AppData\\Local\\Programs\\Python\\Python39\\lib\\site-packages\\selenium\\webdriver\\remote\\webdriver.py\", line 268, in __init__\n    self.start_session(capabilities, browser_profile)\n  File \"C:\\Users\\chandrakant\\AppData\\Local\\Programs\\Python\\Python39\\lib\\site-packages\\appium\\webdriver\\webdriver.py\", line 357, in start_session\n    response = self.execute(RemoteCommand.NEW_SESSION, parameters)\n  File \"C:\\Users\\chandrakant\\AppData\\Local\\Programs\\Python\\Python39\\lib\\site-packages\\selenium\\webdriver\\remote\\webdriver.py\", line 424, in execute\n    self.error_handler.check_response(response)\n  File \"C:\\Users\\chandrakant\\AppData\\Local\\Programs\\Python\\Python39\\lib\\site-packages\\selenium\\webdriver\\remote\\errorhandler.py\", line 247, in check_response\n    raise exception_class(message, screen, stacktrace)\n"}, "start": 1641358614651, "stop": 1641358616043}], "start": 1641358614651, "stop": 1641358616119}